Workbook

Sheet Weighting Reg Results
A1: SUMMARY OUTPUT
A3: Regression Statistics
A4: Multiple R | B4: 0.94322725
A5: R Square | B5: 0.88967764
A6: Adjusted R Square | B6: 0.85624663
A7: Standard Error | B7: 10944.402
A8: Observations | B8: 44
A10: ANOVA
B11: df | C11: SS | D11: MS | E11: F | F11: Significance F
A12: Regression | B12: 10 | C12: 3.1876245e+10 | D12: 3.1876245e+09 | E12: 26.612342 | F12: 5.5596547e-13
A13: Residual | B13: 33 | C13: 3.9527378e+09 | D13: 1.1977993e+08
A14: Total | B14: 43 | C14: 3.5828983e+10
B16: Coefficients | C16: Standard Error | D16: t Stat | E16: P-value | F16: Lower 95% | G16: Upper 95% | H16: Lower 95.0% | I16: Upper 95.0%
A17: Intercept | B17: -22748.9 | C17: 10804.037 | D17: -2.1055926 | E17: 0.042932352 | F17: -44729.879 | G17: -767.92178 | H17: -44729.879 | I17: -767.92178
A18: Education | B18: 2269.2016 | C18: 2850.26 | D18: 0.79613843 | E18: 0.4316418 | F18: -3529.6961 | G18: 8068.0992 | H18: -3529.6961 | I18: 8068.0992
A19: Experience | B19: 4356.0717 | C19: 2213.2026 | D19: 1.968221 | E19: 0.057491241 | F19: -146.72277 | G19: 8858.8662 | H19: -146.72277 | I19: 8858.8662
A20: Purpose of Contacts | B20: 1338.1545 | C20: 2824.3812 | D20: 0.4737868 | E20: 0.63877163 | F20: -4408.0922 | G20: 7084.4013 | H20: -4408.0922 | I20: 7084.4013
A21: Decision Making | B21: 6479.9513 | C21: 3784.4607 | D21: 1.7122522 | E21: 0.096233705 | F21: -1219.5919 | G21: 14179.494 | H21: -1219.5919 | I21: 14179.494
A22: Accountability | B22: -12070.15 | C22: 3419.7159 | D22: -3.5295769 | E22: 0.0012502453 | F22: -19027.615 | G22: -5112.6861 | H22: -19027.615 | I22: -5112.6861
A23: Contract Management | B23: 3045.7428 | C23: 2676.5953 | D23: 1.1379168 | E23: 0.26334969 | F23: -2399.8313 | G23: 8491.3169 | H23: -2399.8313 | I23: 8491.3169
A24: Budget | B24: 16736.869 | C24: 4421.591 | D24: 3.7852594 | E24: 0.00061624833 | F24: 7741.0744 | G24: 25732.663 | H24: 7741.0744 | I24: 25732.663
A25: Customer Service | B25: 6337.8495 | C25: 2640.9486 | D25: 2.3998383 | E25: 0.022204558 | F25: 964.79926 | G25: 11710.9 | H25: 964.79926 | I25: 11710.9
A26: Working Conditions | B26: 9503.7582 | C26: 3167.0283 | D26: 3.0008441 | E26: 0.0050960439 | F26: 3060.3907 | G26: 15947.126 | H26: 3060.3907 | I26: 15947.126
A27: Work Demands | B27: 7376.0292 | C27: 3267.5312 | D27: 2.2573707 | E27: 0.030725581 | F27: 728.18699 | G27: 14023.871 | H27: 728.18699 | I27: 14023.871

Sheet Points Schedule
H1: Points Schedule
B2: CFs | C2: Coefficients | D2: Weight | E2: Degree Levels | F2: Points | G2: Degree Level: | H2: 1 | I2: 2 | J2: 3 | K2: 4 | L2: 5 | M2: 6
B3: Education | C3: 2269.2016 | D3: =C3/$C$13 -> 0.039503103 | E3: 5 | F3: =1000*D3/E3 -> 7.9006206 | H3: 10 | I3: =H3+$H$3 -> 20 | J3: =I3+$H$3 -> 30 | K3: =J3+$H$3 -> 40 | L3: =K3+$H$3 -> 50
B4: Experience | C4: 4356.0717 | D4: =C4/$C$13 -> 0.075832114 | E4: 6 | F4: =1000*D4/E4 -> 12.638686 | H4: 15 | I4: =H4+$H$4 -> 30 | J4: =I4+$H$4 -> 45 | K4: =J4+$H$4 -> 60 | L4: =K4+$H$4 -> 75 | M4: =L4+$H$4 -> 90
B5: Purpose of Contacts | C5: 1338.1545 | D5: =C5/$C$13 -> 0.023295091 | E5: 6 | F5: =1000*D5/E5 -> 3.8825151 | H5: 5 | I5: =H5+$H$5 -> 10 | J5: =I5+$H$5 -> 15 | K5: =J5+$H$5 -> 20 | L5: =K5+$H$5 -> 25 | M5: =L5+$H$5 -> 30
B6: Decision Making | C6: 6479.9513 | D6: =C6/$C$13 -> 0.1128054 | E6: 5 | F6: =1000*D6/E6 -> 22.561079 | H6: 25 | I6: =H6+$H$6 -> 50 | J6: =I6+$H$6 -> 75 | K6: =J6+$H$6 -> 100 | L6: =K6+$H$6 -> 125
B7: Contract Management | C7: 3045.7428 | D7: =C7/$C$13 -> 0.053021422 | E7: 5 | F7: =1000*D7/E7 -> 10.604284 | H7: 10 | I7: =H7+$H$7 -> 20 | J7: =I7+$H$7 -> 30 | K7: =J7+$H$7 -> 40 | L7: =K7+$H$7 -> 50
B8: Budget | C8: 16736.869 | D8: =C8/$C$13 -> 0.29136163 | E8: 4 | F8: =1000*D8/E8 -> 72.840407 | H8: 70 | I8: =H8+$H$8 -> 140 | J8: =I8+$H$8 -> 210 | K8: =J8+$H$8 -> 280
B9: Customer Service | C9: 6337.8495 | D9: =C9/$C$13 -> 0.11033164 | E9: 5 | F9: =1000*D9/E9 -> 22.066327 | H9: 20 | I9: =H9+$H$9 -> 40 | J9: =I9+$H$9 -> 60 | K9: =J9+$H$9 -> 80 | L9: =K9+$H$9 -> 100
B10: Working Conditions | C10: 9503.7582 | D10: =C10/$C$13 -> 0.16544495 | E10: 4 | F10: =1000*D10/E10 -> 41.361238 | H10: 40 | I10: =H10+$H$10 -> 80 | J10: =I10+$H$10 -> 120 | K10: =J10+$H$10 -> 160
B11: Work Demands | C11: 7376.0292 | D11: =C11/$C$13 -> 0.12840466 | E11: 4 | F11: =1000*D11/E11 -> 32.101164 | H11: 30 | I11: =H11+$H$11 -> 60 | J11: =I11+$H$11 -> 90 | K11: =J11+$H$11 -> 120
B13: Total | C13: =SUM(C3:C11) -> 57443.628 | D13: =SUM(D3:D11) -> 1 | I13: Total Points: | J13: =L3+M4+M5+L6+L7+K8+L9+K10+K11 -> 1005

Sheet Clusters
A1: Cluster | B1: Min Points | C1: Max Points | D1: Point Difference | E1: % spread
A2: 1 | B2: =MIN(Data!W3:W46) -> 255 | C2: =B2+D2 -> 257.55 | D2: =B2*E2 -> 2.55 | E2: 0.01
A3: 2 | B3: =C2+1 -> 258.55 | C3: =B3+D3 -> 268.892 | D3: =B3*E3 -> 10.342 | E3: =E2+3% -> 0.04
A4: 3 | B4: =C3+1 -> 269.892 | C4: =B4+D4 -> 288.78444 | D4: =B4*E4 -> 18.89244 | E4: =E3+3% -> 0.07
A5: 4 | B5: =C4+1 -> 289.78444 | C5: =B5+D5 -> 318.76288 | D5: =B5*E5 -> 28.978444 | E5: =E4+3% -> 0.1
A6: 5 | B6: =C5+1 -> 319.76288 | C6: =B6+D6 -> 361.33206 | D6: =B6*E6 -> 41.569175 | E6: =E5+3% -> 0.13
A7: 6 | B7: =C6+1 -> 362.33206 | C7: =B7+D7 -> 420.30519 | D7: =B7*E7 -> 57.973129 | E7: =E6+3% -> 0.16
A8: 7 | B8: =C7+1 -> 421.30519 | C8: =B8+D8 -> 501.35317 | D8: =B8*E8 -> 80.047986 | E8: =E7+3% -> 0.19
A9: 8 | B9: =C8+1 -> 502.35317 | C9: =B9+D9 -> 612.87087 | D9: =B9*E9 -> 110.5177 | E9: =E8+3% -> 0.22
A10: 9 | B10: =C9+1 -> 613.87087 | C10: =B10+D10 -> 767.33859 | D10: =B10*E10 -> 153.46772 | E10: =E9+3% -> 0.25
A11: 10 | B11: =C10+1 -> 768.33859 | C11: =B11+D11 -> 983.4734 | D11: =B11*E11 -> 215.13481 | E11: =E10+3% -> 0.28
A12: 11 | B12: =C11+1 -> 984.4734 | C12: =B12+D12 -> 1289.6601 | D12: =B12*E12 -> 305.18675 | E12: =E11+3% -> 0.31
A13: 12 | B13: =C12+1 -> 1290.6601 | C13: =B13+D13 -> 1729.4846 | D13: =B13*E13 -> 438.82445 | E13: =E12+3% -> 0.34
A14: 13 | B14: =C13+1 -> 1730.4846 | C14: =B14+D14 -> 2370.7639 | D14: =B14*E14 -> 640.2793 | E14: =E13+3% -> 0.37

Sheet Data
D1: SKILLS | G1: RESPONSIBILITY | L1: CONDITIONS | M1: EFFORT
A2: Position Title | B2: Department | C2: 2007 Salary | D2: Education | E2: Experience | F2: Purpose of Contacts | G2: Decision Making | H2: Accountability | I2: Contract Management | J2: Budget | K2: Customer Service | L2: Working Conditions | M2: Work Demands | N2: points_education | O2: points_experience | P2: points_purpose_contacts | Q2: points_decision | R2: points_contract | S2: points_budget | T2: points_customer | U2: points_conditions | V2: points_demands | W2: Total Points | X2: Cluster | Y2: Benchmark (in thousands of dollars) | Z2: Benchmark
A3: Administrative Clerk | B3: Quality Assurance | C3: 36260 | D3: 1 | E3: 1 | F3: 1 | G3: 1 | H3: 1 | I3: 1 | J3: 1 | K3: 1 | L3: 1 | M3: 2 | N3: =INDEX('Points Schedule'!$H$3:$M$3, MATCH(D3, 'Points Schedule'!$H$2:$M$2, 0)) -> 10 | O3: =INDEX('Points Schedule'!$H$4:$M$4, MATCH(E3, 'Points Schedule'!$H$2:$M$2, 0)) -> 15 | P3: =INDEX('Points Schedule'!$H$5:$M$5, MATCH(F3, 'Points Schedule'!$H$2:$M$2, 0)) -> 5 | Q3: =INDEX('Points Schedule'!$H$6:$M$6, MATCH(G3, 'Points Schedule'!$H$2:$M$2, 0)) -> 25 | R3: =INDEX('Points Schedule'!$H$7:$M$7, MATCH(I3, 'Points Schedule'!$H$2:$M$2, 0)) -> 10 | S3: =INDEX('Points Schedule'!$H$8:$M$8, MATCH(J3, 'Points Schedule'!$H$2:$M$2, 0)) -> 70 | T3: =INDEX('Points Schedule'!$H$9:$M$9, MATCH(K3, 'Points Schedule'!$H$2:$M$2, 0)) -> 20 | U3: =INDEX('Points Schedule'!$H$10:$M$10, MATCH(L3, 'Points Schedule'!$H$2:$M$2, 0)) -> 40 | V3: =INDEX('Points Schedule'!$H$11:$M$11, MATCH(M3, 'Points Schedule'!$H$2:$M$2, 0)) -> 60 | W3: =SUM(N3:V3) -> 255 | X3: {=INDEX(Clusters!A:A, MATCH(1, (W3>=Clusters!B:B)*(W3<=Clusters!C:C), 0))} -> 1 | Y3: 38.372611 | Z3: =Y3*1000 -> 38372.611
A4: Receptionist | B4: Ops | C4: 44526 | D4: 1 | E4: 2 | F4: 1 | G4: 1 | H4: 1 | I4: 1 | J4: 1 | K4: 2 | L4: 1 | M4: 1 | N4: =INDEX('Points Schedule'!$H$3:$M$3, MATCH(D4, 'Points Schedule'!$H$2:$M$2, 0)) -> 10 | O4: =INDEX('Points Schedule'!$H$4:$M$4, MATCH(E4, 'Points Schedule'!$H$2:$M$2, 0)) -> 30 | P4: =INDEX('Points Schedule'!$H$5:$M$5, MATCH(F4, 'Points Schedule'!$H$2:$M$2, 0)) -> 5 | Q4: =INDEX('Points Schedule'!$H$6:$M$6, MATCH(G4, 'Points Schedule'!$H$2:$M$2, 0)) -> 25 | R4: =INDEX('Points Schedule'!$H$7:$M$7, MATCH(I4, 'Points Schedule'!$H$2:$M$2, 0)) -> 10 | S4: =INDEX('Points Schedule'!$H$8:$M$8, MATCH(J4, 'Points Schedule'!$H$2:$M$2, 0)) -> 70 | T4: =INDEX('Points Schedule'!$H$9:$M$9, MATCH(K4, 'Points Schedule'!$H$2:$M$2, 0)) -> 40 | U4: =INDEX('Points Schedule'!$H$10:$M$10, MATCH(L4, 'Points Schedule'!$H$2:$M$2, 0)) -> 40 | V4: =INDEX('Points Schedule'!$H$11:$M$11, MATCH(M4, 'Points Schedule'!$H$2:$M$2, 0)) -> 30 | W4: =SUM(N4:V4) -> 260 | X4: {=INDEX(Clusters!A:A, MATCH(1, (W4>=Clusters!B:B)*(W4<=Clusters!C:C), 0))} -> 2 | Y4: 35.2879 | Z4: =Y4*1000 -> 35287.9
A5: Administrative Clerk | B5: Ops | C5: 36113 | D5: 1 | E5: 1 | F5: 1 | G5: 1 | H5: 1 | I5: 2 | J5: 1 | K5: 1 | L5: 1 | M5: 2 | N5: =INDEX('Points Schedule'!$H$3:$M$3, MATCH(D5, 'Points Schedule'!$H$2:$M$2, 0)) -> 10 | O5: =INDEX('Points Schedule'!$H$4:$M$4, MATCH(E5, 'Points Schedule'!$H$2:$M$2, 0)) -> 15 | P5: =INDEX('Points Schedule'!$H$5:$M$5, MATCH(F5, 'Points Schedule'!$H$2:$M$2, 0)) -> 5 | Q5: =INDEX('Points Schedule'!$H$6:$M$6, MATCH(G5, 'Points Schedule'!$H$2:$M$2, 0)) -> 25 | R5: =INDEX('Points Schedule'!$H$7:$M$7, MATCH(I5, 'Points Schedule'!$H$2:$M$2, 0)) -> 20 | S5: =INDEX('Points Schedule'!$H$8:$M$8, MATCH(J5, 'Points Schedule'!$H$2:$M$2, 0)) -> 70 | T5: =INDEX('Points Schedule'!$H$9:$M$9, MATCH(K5, 'Points Schedule'!$H$2:$M$2, 0)) -> 20 | U5: =INDEX('Points Schedule'!$H$10:$M$10, MATCH(L5, 'Points Schedule'!$H$2:$M$2, 0)) -> 40 | V5: =INDEX('Points Schedule'!$H$11:$M$11, MATCH(M5, 'Points Schedule'!$H$2:$M$2, 0)) -> 60 | W5: =SUM(N5:V5) -> 265 | X5: {=INDEX(Clusters!A:A, MATCH(1, (W5>=Clusters!B:B)*(W5<=Clusters!C:C), 0))} -> 2 | Y5: 38.372611 | Z5: =Y5*1000 -> 38372.611
A6: Administrative Clerk | B6: Ops | C6: 32008 | D6: 1 | E6: 1 | F6: 1 | G6: 1 | H6: 1 | I6: 2 | J6: 1 | K6: 1 | L6: 1 | M6: 2 | N6: =INDEX('Points Schedule'!$H$3:$M$3, MATCH(D6, 'Points Schedule'!$H$2:$M$2, 0)) -> 10 | O6: =INDEX('Points Schedule'!$H$4:$M$4, MATCH(E6, 'Points Schedule'!$H$2:$M$2, 0)) -> 15 | P6: =INDEX('Points Schedule'!$H$5:$M$5, MATCH(F6, 'Points Schedule'!$H$2:$M$2, 0)) -> 5 | Q6: =INDEX('Points Schedule'!$H$6:$M$6, MATCH(G6, 'Points Schedule'!$H$2:$M$2, 0)) -> 25 | R6: =INDEX('Points Schedule'!$H$7:$M$7, MATCH(I6, 'Points Schedule'!$H$2:$M$2, 0)) -> 20 | S6: =INDEX('Points Schedule'!$H$8:$M$8, MATCH(J6, 'Points Schedule'!$H$2:$M$2, 0)) -> 70 | T6: =INDEX('Points Schedule'!$H$9:$M$9, MATCH(K6, 'Points Schedule'!$H$2:$M$2, 0)) -> 20 | U6: =INDEX('Points Schedule'!$H$10:$M$10, MATCH(L6, 'Points Schedule'!$H$2:$M$2, 0)) -> 40 | V6: =INDEX('Points Schedule'!$H$11:$M$11, MATCH(M6, 'Points Schedule'!$H$2:$M$2, 0)) -> 60 | W6: =SUM(N6:V6) -> 265 | X6: {=INDEX(Clusters!A:A, MATCH(1, (W6>=Clusters!B:B)*(W6<=Clusters!C:C), 0))} -> 2 | Y6: 38.372611 | Z6: =Y6*1000 -> 38372.611
A7: Meetings and District Programs Coordinator | B7: Continuing Education | C7: 42908 | D7: 3 | E7: 1 | F7: 2 | G7: 1 | H7: 1 | I7: 2 | J7: 1 | K7: 2 | L7: 1 | M7: 1 | N7: =INDEX('Points Schedule'!$H$3:$M$3, MATCH(D7, 'Points Schedule'!$H$2:$M$2, 0)) -> 30 | O7: =INDEX('Points Schedule'!$H$4:$M$4, MATCH(E7, 'Points Schedule'!$H$2:$M$2, 0)) -> 15 | P7: =INDEX('Points Schedule'!$H$5:$M$5, MATCH(F7, 'Points Schedule'!$H$2:$M$2, 0)) -> 10 | Q7: =INDEX('Points Schedule'!$H$6:$M$6, MATCH(G7, 'Points Schedule'!$H$2:$M$2, 0)) -> 25 | R7: =INDEX('Points Schedule'!$H$7:$M$7, MATCH(I7, 'Points Schedule'!$H$2:$M$2, 0)) -> 20 | S7: =INDEX('Points Schedule'!$H$8:$M$8, MATCH(J7, 'Points Schedule'!$H$2:$M$2, 0)) -> 70 | T7: =INDEX('Points Schedule'!$H$9:$M$9, MATCH(K7, 'Points Schedule'!$H$2:$M$2, 0)) -> 40 | U7: =INDEX('Points Schedule'!$H$10:$M$10, MATCH(L7, 'Points Schedule'!$H$2:$M$2, 0)) -> 40 | V7: =INDEX('Points Schedule'!$H$11:$M$11, MATCH(M7, 'Points Schedule'!$H$2:$M$2, 0)) -> 30 | W7: =SUM(N7:V7) -> 280 | X7: 3 | Y7: 50.257143 | Z7: =Y7*1000 -> 50257.143
A8: Circulation Technician & Receptionist | B8: Ops | C8: 46481 | D8: 3 | E8: 2 | F8: 1 | G8: 1 | H8: 1 | I8: 1 | J8: 1 | K8: 2 | L8: 1 | M8: 1 | N8: =INDEX('Points Schedule'!$H$3:$M$3, MATCH(D8, 'Points Schedule'!$H$2:$M$2, 0)) -> 30 | O8: =INDEX('Points Schedule'!$H$4:$M$4, MATCH(E8, 'Points Schedule'!$H$2:$M$2, 0)) -> 30 | P8: =INDEX('Points Schedule'!$H$5:$M$5, MATCH(F8, 'Points Schedule'!$H$2:$M$2, 0)) -> 5 | Q8: =INDEX('Points Schedule'!$H$6:$M$6, MATCH(G8, 'Points Schedule'!$H$2:$M$2, 0)) -> 25 | R8: =INDEX('Points Schedule'!$H$7:$M$7, MATCH(I8, 'Points Schedule'!$H$2:$M$2, 0)) -> 10 | S8: =INDEX('Points Schedule'!$H$8:$M$8, MATCH(J8, 'Points Schedule'!$H$2:$M$2, 0)) -> 70 | T8: =INDEX('Points Schedule'!$H$9:$M$9, MATCH(K8, 'Points Schedule'!$H$2:$M$2, 0)) -> 40 | U8: =INDEX('Points Schedule'!$H$10:$M$10, MATCH(L8, 'Points Schedule'!$H$2:$M$2, 0)) -> 40 | V8: =INDEX('Points Schedule'!$H$11:$M$11, MATCH(M8, 'Points Schedule'!$H$2:$M$2, 0)) -> 30 | W8: =SUM(N8:V8) -> 280 | X8: {=INDEX(Clusters!A:A, MATCH(1, (W8>=Clusters!B:B)*(W8<=Clusters!C:C), 0))} -> 3
A9: Seminar Coordinator | B9: Continuing Education | C9: 38513 | D9: 3 | E9: 1 | F9: 2 | G9: 1 | H9: 1 | I9: 2 | J9: 1 | K9: 2 | L9: 1 | M9: 1 | N9: =INDEX('Points Schedule'!$H$3:$M$3, MATCH(D9, 'Points Schedule'!$H$2:$M$2, 0)) -> 30 | O9: =INDEX('Points Schedule'!$H$4:$M$4, MATCH(E9, 'Points Schedule'!$H$2:$M$2, 0)) -> 15 | P9: =INDEX('Points Schedule'!$H$5:$M$5, MATCH(F9, 'Points Schedule'!$H$2:$M$2, 0)) -> 10 | Q9: =INDEX('Points Schedule'!$H$6:$M$6, MATCH(G9, 'Points Schedule'!$H$2:$M$2, 0)) -> 25 | R9: =INDEX('Points Schedule'!$H$7:$M$7, MATCH(I9, 'Points Schedule'!$H$2:$M$2, 0)) -> 20 | S9: =INDEX('Points Schedule'!$H$8:$M$8, MATCH(J9, 'Points Schedule'!$H$2:$M$2, 0)) -> 70 | T9: =INDEX('Points Schedule'!$H$9:$M$9, MATCH(K9, 'Points Schedule'!$H$2:$M$2, 0)) -> 40 | U9: =INDEX('Points Schedule'!$H$10:$M$10, MATCH(L9, 'Points Schedule'!$H$2:$M$2, 0)) -> 40 | V9: =INDEX('Points Schedule'!$H$11:$M$11, MATCH(M9, 'Points Schedule'!$H$2:$M$2, 0)) -> 30 | W9: =SUM(N9:V9) -> 280 | X9: {=INDEX(Clusters!A:A, MATCH(1, (W9>=Clusters!B:B)*(W9<=Clusters!C:C), 0))} -> 3 | Y9: 50.257143 | Z9: =Y9*1000 -> 50257.143
A10: Seminar Coordinator | B10: Continuing Education | C10: 37370 | D10: 3 | E10: 1 | F10: 2 | G10: 1 | H10: 1 | I10: 2 | J10: 1 | K10: 2 | L10: 1 | M10: 1 | N10: =INDEX('Points Schedule'!$H$3:$M$3, MATCH(D10, 'Points Schedule'!$H$2:$M$2, 0)) -> 30 | O10: =INDEX('Points Schedule'!$H$4:$M$4, MATCH(E10, 'Points Schedule'!$H$2:$M$2, 0)) -> 15 | P10: =INDEX('Points Schedule'!$H$5:$M$5, MATCH(F10, 'Points Schedule'!$H$2:$M$2, 0)) -> 10 | Q10: =INDEX('Points Schedule'!$H$6:$M$6, MATCH(G10, 'Points Schedule'!$H$2:$M$2, 0)) -> 25 | R10: =INDEX('Points Schedule'!$H$7:$M$7, MATCH(I10, 'Points Schedule'!$H$2:$M$2, 0)) -> 20 | S10: =INDEX('Points Schedule'!$H$8:$M$8, MATCH(J10, 'Points Schedule'!$H$2:$M$2, 0)) -> 70 | T10: =INDEX('Points Schedule'!$H$9:$M$9, MATCH(K10, 'Points Schedule'!$H$2:$M$2, 0)) -> 40 | U10: =INDEX('Points Schedule'!$H$10:$M$10, MATCH(L10, 'Points Schedule'!$H$2:$M$2, 0)) -> 40 | V10: =INDEX('Points Schedule'!$H$11:$M$11, MATCH(M10, 'Points Schedule'!$H$2:$M$2, 0)) -> 30 | W10: =SUM(N10:V10) -> 280 | X10: {=INDEX(Clusters!A:A, MATCH(1, (W10>=Clusters!B:B)*(W10<=Clusters!C:C), 0))} -> 3 | Y10: 50.257143 | Z10: =Y10*1000 -> 50257.143
A11: Secretary (Director Continuing Education) | B11: Continuing Education | C11: 43898 | D11: 2 | E11: 1 | F11: 1 | G11: 1 | H11: 1 | I11: 2 | J11: 1 | K11: 3 | L11: 1 | M11: 1 | N11: =INDEX('Points Schedule'!$H$3:$M$3, MATCH(D11, 'Points Schedule'!$H$2:$M$2, 0)) -> 20 | O11: =INDEX('Points Schedule'!$H$4:$M$4, MATCH(E11, 'Points Schedule'!$H$2:$M$2, 0)) -> 15 | P11: =INDEX('Points Schedule'!$H$5:$M$5, MATCH(F11, 'Points Schedule'!$H$2:$M$2, 0)) -> 5 | Q11: =INDEX('Points Schedule'!$H$6:$M$6, MATCH(G11, 'Points Schedule'!$H$2:$M$2, 0)) -> 25 | R11: =INDEX('Points Schedule'!$H$7:$M$7, MATCH(I11, 'Points Schedule'!$H$2:$M$2, 0)) -> 20 | S11: =INDEX('Points Schedule'!$H$8:$M$8, MATCH(J11, 'Points Schedule'!$H$2:$M$2, 0)) -> 70 | T11: =INDEX('Points Schedule'!$H$9:$M$9, MATCH(K11, 'Points Schedule'!$H$2:$M$2, 0)) -> 60 | U11: =INDEX('Points Schedule'!$H$10:$M$10, MATCH(L11, 'Points Schedule'!$H$2:$M$2, 0)) -> 40 | V11: =INDEX('Points Schedule'!$H$11:$M$11, MATCH(M11, 'Points Schedule'!$H$2:$M$2, 0)) -> 30 | W11: =SUM(N11:V11) -> 285 | X11: {=INDEX(Clusters!A:A, MATCH(1, (W11>=Clusters!B:B)*(W11<=Clusters!C:C), 0))} -> 3 | Y11: 47.838276 | Z11: =Y11*1000 -> 47838.276
A12: Junior Systems Administrator | B12: IT | C12: 41500 | D12: 3 | E12: 1 | F12: 1 | G12: 2 | H12: 1 | I12: 1 | J12: 1 | K12: 2 | L12: 1 | M12: 1 | N12: =INDEX('Points Schedule'!$H$3:$M$3, MATCH(D12, 'Points Schedule'!$H$2:$M$2, 0)) -> 30 | O12: =INDEX('Points Schedule'!$H$4:$M$4, MATCH(E12, 'Points Schedule'!$H$2:$M$2, 0)) -> 15 | P12: =INDEX('Points Schedule'!$H$5:$M$5, MATCH(F12, 'Points Schedule'!$H$2:$M$2, 0)) -> 5 | Q12: =INDEX('Points Schedule'!$H$6:$M$6, MATCH(G12, 'Points Schedule'!$H$2:$M$2, 0)) -> 50 | R12: =INDEX('Points Schedule'!$H$7:$M$7, MATCH(I12, 'Points Schedule'!$H$2:$M$2, 0)) -> 10 | S12: =INDEX('Points Schedule'!$H$8:$M$8, MATCH(J12, 'Points Schedule'!$H$2:$M$2, 0)) -> 70 | T12: =INDEX('Points Schedule'!$H$9:$M$9, MATCH(K12, 'Points Schedule'!$H$2:$M$2, 0)) -> 40 | U12: =INDEX('Points Schedule'!$H$10:$M$10, MATCH(L12, 'Points Schedule'!$H$2:$M$2, 0)) -> 40 | V12: =INDEX('Points Schedule'!$H$11:$M$11, MATCH(M12, 'Points Schedule'!$H$2:$M$2, 0)) -> 30 | W12: =SUM(N12:V12) -> 290 | X12: {=INDEX(Clusters!A:A, MATCH(1, (W12>=Clusters!B:B)*(W12<=Clusters!C:C), 0))} -> 4
A13: Administrative Assistant, Exec Office | B13: Exec | C13: 37258 | D13: 1 | E13: 1 | F13: 2 | G13: 1 | H13: 1 | I13: 1 | J13: 1 | K13: 2 | L13: 2 | M13: 1 | N13: =INDEX('Points Schedule'!$H$3:$M$3, MATCH(D13, 'Points Schedule'!$H$2:$M$2, 0)) -> 10 | O13: =INDEX('Points Schedule'!$H$4:$M$4, MATCH(E13, 'Points Schedule'!$H$2:$M$2, 0)) -> 15 | P13: =INDEX('Points Schedule'!$H$5:$M$5, MATCH(F13, 'Points Schedule'!$H$2:$M$2, 0)) -> 10 | Q13: =INDEX('Points Schedule'!$H$6:$M$6, MATCH(G13, 'Points Schedule'!$H$2:$M$2, 0)) -> 25 | R13: =INDEX('Points Schedule'!$H$7:$M$7, MATCH(I13, 'Points Schedule'!$H$2:$M$2, 0)) -> 10 | S13: =INDEX('Points Schedule'!$H$8:$M$8, MATCH(J13, 'Points Schedule'!$H$2:$M$2, 0)) -> 70 | T13: =INDEX('Points Schedule'!$H$9:$M$9, MATCH(K13, 'Points Schedule'!$H$2:$M$2, 0)) -> 40 | U13: =INDEX('Points Schedule'!$H$10:$M$10, MATCH(L13, 'Points Schedule'!$H$2:$M$2, 0)) -> 80 | V13: =INDEX('Points Schedule'!$H$11:$M$11, MATCH(M13, 'Points Schedule'!$H$2:$M$2, 0)) -> 30 | W13: =SUM(N13:V13) -> 290 | X13: {=INDEX(Clusters!A:A, MATCH(1, (W13>=Clusters!B:B)*(W13<=Clusters!C:C), 0))} -> 4 | Y13: 55.49247 | Z13: =Y13*1000 -> 55492.47
A14: Junior Accountant | B14: Ops | C14: 32810 | D14: 2 | E14: 1 | F14: 1 | G14: 1 | H14: 1 | I14: 2 | J14: 1 | K14: 2 | L14: 1 | M14: 2 | N14: =INDEX('Points Schedule'!$H$3:$M$3, MATCH(D14, 'Points Schedule'!$H$2:$M$2, 0)) -> 20 | O14: =INDEX('Points Schedule'!$H$4:$M$4, MATCH(E14, 'Points Schedule'!$H$2:$M$2, 0)) -> 15 | P14: =INDEX('Points Schedule'!$H$5:$M$5, MATCH(F14, 'Points Schedule'!$H$2:$M$2, 0)) -> 5 | Q14: =INDEX('Points Schedule'!$H$6:$M$6, MATCH(G14, 'Points Schedule'!$H$2:$M$2, 0)) -> 25 | R14: =INDEX('Points Schedule'!$H$7:$M$7, MATCH(I14, 'Points Schedule'!$H$2:$M$2, 0)) -> 20 | S14: =INDEX('Points Schedule'!$H$8:$M$8, MATCH(J14, 'Points Schedule'!$H$2:$M$2, 0)) -> 70 | T14: =INDEX('Points Schedule'!$H$9:$M$9, MATCH(K14, 'Points Schedule'!$H$2:$M$2, 0)) -> 40 | U14: =INDEX('Points Schedule'!$H$10:$M$10, MATCH(L14, 'Points Schedule'!$H$2:$M$2, 0)) -> 40 | V14: =INDEX('Points Schedule'!$H$11:$M$11, MATCH(M14, 'Points Schedule'!$H$2:$M$2, 0)) -> 60 | W14: =SUM(N14:V14) -> 295 | X14: {=INDEX(Clusters!A:A, MATCH(1, (W14>=Clusters!B:B)*(W14<=Clusters!C:C), 0))} -> 4 | Y14: 44.119737 | Z14: =Y14*1000 -> 44119.737
A15: Business Research Coordinator | B15: Ops | C15: 58000 | D15: 3 | E15: 2 | F15: 2 | G15: 1 | H15: 1 | I15: 2 | J15: 1 | K15: 2 | L15: 1 | M15: 1 | N15: =INDEX('Points Schedule'!$H$3:$M$3, MATCH(D15, 'Points Schedule'!$H$2:$M$2, 0)) -> 30 | O15: =INDEX('Points Schedule'!$H$4:$M$4, MATCH(E15, 'Points Schedule'!$H$2:$M$2, 0)) -> 30 | P15: =INDEX('Points Schedule'!$H$5:$M$5, MATCH(F15, 'Points Schedule'!$H$2:$M$2, 0)) -> 10 | Q15: =INDEX('Points Schedule'!$H$6:$M$6, MATCH(G15, 'Points Schedule'!$H$2:$M$2, 0)) -> 25 | R15: =INDEX('Points Schedule'!$H$7:$M$7, MATCH(I15, 'Points Schedule'!$H$2:$M$2, 0)) -> 20 | S15: =INDEX('Points Schedule'!$H$8:$M$8, MATCH(J15, 'Points Schedule'!$H$2:$M$2, 0)) -> 70 | T15: =INDEX('Points Schedule'!$H$9:$M$9, MATCH(K15, 'Points Schedule'!$H$2:$M$2, 0)) -> 40 | U15: =INDEX('Points Schedule'!$H$10:$M$10, MATCH(L15, 'Points Schedule'!$H$2:$M$2, 0)) -> 40 | V15: =INDEX('Points Schedule'!$H$11:$M$11, MATCH(M15, 'Points Schedule'!$H$2:$M$2, 0)) -> 30 | W15: =SUM(N15:V15) -> 295 | X15: {=INDEX(Clusters!A:A, MATCH(1, (W15>=Clusters!B:B)*(W15<=Clusters!C:C), 0))} -> 4
A16: Administrative Clerk/mailroom clerk | B16: Ops | C16: 40429 | D16: 1 | E16: 1 | F16: 2 | G16: 1 | H16: 1 | I16: 1 | J16: 1 | K16: 1 | L16: 3 | M16: 1 | N16: =INDEX('Points Schedule'!$H$3:$M$3, MATCH(D16, 'Points Schedule'!$H$2:$M$2, 0)) -> 10 | O16: =INDEX('Points Schedule'!$H$4:$M$4, MATCH(E16, 'Points Schedule'!$H$2:$M$2, 0)) -> 15 | P16: =INDEX('Points Schedule'!$H$5:$M$5, MATCH(F16, 'Points Schedule'!$H$2:$M$2, 0)) -> 10 | Q16: =INDEX('Points Schedule'!$H$6:$M$6, MATCH(G16, 'Points Schedule'!$H$2:$M$2, 0)) -> 25 | R16: =INDEX('Points Schedule'!$H$7:$M$7, MATCH(I16, 'Points Schedule'!$H$2:$M$2, 0)) -> 10 | S16: =INDEX('Points Schedule'!$H$8:$M$8, MATCH(J16, 'Points Schedule'!$H$2:$M$2, 0)) -> 70 | T16: =INDEX('Points Schedule'!$H$9:$M$9, MATCH(K16, 'Points Schedule'!$H$2:$M$2, 0)) -> 20 | U16: =INDEX('Points Schedule'!$H$10:$M$10, MATCH(L16, 'Points Schedule'!$H$2:$M$2, 0)) -> 120 | V16: =INDEX('Points Schedule'!$H$11:$M$11, MATCH(M16, 'Points Schedule'!$H$2:$M$2, 0)) -> 30 | W16: =SUM(N16:V16) -> 310 | X16: {=INDEX(Clusters!A:A, MATCH(1, (W16>=Clusters!B:B)*(W16<=Clusters!C:C), 0))} -> 4 | Y16: 39.200926 | Z16: =Y16*1000 -> 39200.926
A17: Accountant | B17: Ops | C17: 41530 | D17: 3 | E17: 2 | F17: 2 | G17: 2 | H17: 1 | I17: 2 | J17: 1 | K17: 1 | L17: 1 | M17: 2 | N17: =INDEX('Points Schedule'!$H$3:$M$3, MATCH(D17, 'Points Schedule'!$H$2:$M$2, 0)) -> 30 | O17: =INDEX('Points Schedule'!$H$4:$M$4, MATCH(E17, 'Points Schedule'!$H$2:$M$2, 0)) -> 30 | P17: =INDEX('Points Schedule'!$H$5:$M$5, MATCH(F17, 'Points Schedule'!$H$2:$M$2, 0)) -> 10 | Q17: =INDEX('Points Schedule'!$H$6:$M$6, MATCH(G17, 'Points Schedule'!$H$2:$M$2, 0)) -> 50 | R17: =INDEX('Points Schedule'!$H$7:$M$7, MATCH(I17, 'Points Schedule'!$H$2:$M$2, 0)) -> 20 | S17: =INDEX('Points Schedule'!$H$8:$M$8, MATCH(J17, 'Points Schedule'!$H$2:$M$2, 0)) -> 70 | T17: =INDEX('Points Schedule'!$H$9:$M$9, MATCH(K17, 'Points Schedule'!$H$2:$M$2, 0)) -> 20 | U17: =INDEX('Points Schedule'!$H$10:$M$10, MATCH(L17, 'Points Schedule'!$H$2:$M$2, 0)) -> 40 | V17: =INDEX('Points Schedule'!$H$11:$M$11, MATCH(M17, 'Points Schedule'!$H$2:$M$2, 0)) -> 60 | W17: =SUM(N17:V17) -> 330 | X17: {=INDEX(Clusters!A:A, MATCH(1, (W17>=Clusters!B:B)*(W17<=Clusters!C:C), 0))} -> 5 | Y17: 53.229843 | Z17: =Y17*1000 -> 53229.843
A18: Programmer | B18: IT | C18: 77289 | D18: 3 | E18: 2 | F18: 1 | G18: 2 | H18: 1 | I18: 1 | J18: 1 | K18: 2 | L18: 1 | M18: 2 | N18: =INDEX('Points Schedule'!$H$3:$M$3, MATCH(D18, 'Points Schedule'!$H$2:$M$2, 0)) -> 30 | O18: =INDEX('Points Schedule'!$H$4:$M$4, MATCH(E18, 'Points Schedule'!$H$2:$M$2, 0)) -> 30 | P18: =INDEX('Points Schedule'!$H$5:$M$5, MATCH(F18, 'Points Schedule'!$H$2:$M$2, 0)) -> 5 | Q18: =INDEX('Points Schedule'!$H$6:$M$6, MATCH(G18, 'Points Schedule'!$H$2:$M$2, 0)) -> 50 | R18: =INDEX('Points Schedule'!$H$7:$M$7, MATCH(I18, 'Points Schedule'!$H$2:$M$2, 0)) -> 10 | S18: =INDEX('Points Schedule'!$H$8:$M$8, MATCH(J18, 'Points Schedule'!$H$2:$M$2, 0)) -> 70 | T18: =INDEX('Points Schedule'!$H$9:$M$9, MATCH(K18, 'Points Schedule'!$H$2:$M$2, 0)) -> 40 | U18: =INDEX('Points Schedule'!$H$10:$M$10, MATCH(L18, 'Points Schedule'!$H$2:$M$2, 0)) -> 40 | V18: =INDEX('Points Schedule'!$H$11:$M$11, MATCH(M18, 'Points Schedule'!$H$2:$M$2, 0)) -> 60 | W18: =SUM(N18:V18) -> 335 | X18: {=INDEX(Clusters!A:A, MATCH(1, (W18>=Clusters!B:B)*(W18<=Clusters!C:C), 0))} -> 5
A19: Career Consultant | B19: Ops | C19: 68700 | D19: 3 | E19: 3 | F19: 2 | G19: 1 | H19: 1 | I19: 1 | J19: 1 | K19: 4 | L19: 1 | M19: 1 | N19: =INDEX('Points Schedule'!$H$3:$M$3, MATCH(D19, 'Points Schedule'!$H$2:$M$2, 0)) -> 30 | O19: =INDEX('Points Schedule'!$H$4:$M$4, MATCH(E19, 'Points Schedule'!$H$2:$M$2, 0)) -> 45 | P19: =INDEX('Points Schedule'!$H$5:$M$5, MATCH(F19, 'Points Schedule'!$H$2:$M$2, 0)) -> 10 | Q19: =INDEX('Points Schedule'!$H$6:$M$6, MATCH(G19, 'Points Schedule'!$H$2:$M$2, 0)) -> 25 | R19: =INDEX('Points Schedule'!$H$7:$M$7, MATCH(I19, 'Points Schedule'!$H$2:$M$2, 0)) -> 10 | S19: =INDEX('Points Schedule'!$H$8:$M$8, MATCH(J19, 'Points Schedule'!$H$2:$M$2, 0)) -> 70 | T19: =INDEX('Points Schedule'!$H$9:$M$9, MATCH(K19, 'Points Schedule'!$H$2:$M$2, 0)) -> 80 | U19: =INDEX('Points Schedule'!$H$10:$M$10, MATCH(L19, 'Points Schedule'!$H$2:$M$2, 0)) -> 40 | V19: =INDEX('Points Schedule'!$H$11:$M$11, MATCH(M19, 'Points Schedule'!$H$2:$M$2, 0)) -> 30 | W19: =SUM(N19:V19) -> 340 | X19: {=INDEX(Clusters!A:A, MATCH(1, (W19>=Clusters!B:B)*(W19<=Clusters!C:C), 0))} -> 5
A20: Associate Coordinator, Professional Programs | B20: Continuing Education | C20: 39104 | D20: 3 | E20: 3 | F20: 1 | G20: 1 | H20: 1 | I20: 1 | J20: 1 | K20: 3 | L20: 1 | M20: 2 | N20: =INDEX('Points Schedule'!$H$3:$M$3, MATCH(D20, 'Points Schedule'!$H$2:$M$2, 0)) -> 30 | O20: =INDEX('Points Schedule'!$H$4:$M$4, MATCH(E20, 'Points Schedule'!$H$2:$M$2, 0)) -> 45 | P20: =INDEX('Points Schedule'!$H$5:$M$5, MATCH(F20, 'Points Schedule'!$H$2:$M$2, 0)) -> 5 | Q20: =INDEX('Points Schedule'!$H$6:$M$6, MATCH(G20, 'Points Schedule'!$H$2:$M$2, 0)) -> 25 | R20: =INDEX('Points Schedule'!$H$7:$M$7, MATCH(I20, 'Points Schedule'!$H$2:$M$2, 0)) -> 10 | S20: =INDEX('Points Schedule'!$H$8:$M$8, MATCH(J20, 'Points Schedule'!$H$2:$M$2, 0)) -> 70 | T20: =INDEX('Points Schedule'!$H$9:$M$9, MATCH(K20, 'Points Schedule'!$H$2:$M$2, 0)) -> 60 | U20: =INDEX('Points Schedule'!$H$10:$M$10, MATCH(L20, 'Points Schedule'!$H$2:$M$2, 0)) -> 40 | V20: =INDEX('Points Schedule'!$H$11:$M$11, MATCH(M20, 'Points Schedule'!$H$2:$M$2, 0)) -> 60 | W20: =SUM(N20:V20) -> 345 | X20: {=INDEX(Clusters!A:A, MATCH(1, (W20>=Clusters!B:B)*(W20<=Clusters!C:C), 0))} -> 5
A21: Secretary (Director Operations) | B21: Ops | C21: 49508 | D21: 2 | E21: 3 | F21: 2 | G21: 1 | H21: 1 | I21: 1 | J21: 1 | K21: 2 | L21: 1 | M21: 3 | N21: =INDEX('Points Schedule'!$H$3:$M$3, MATCH(D21, 'Points Schedule'!$H$2:$M$2, 0)) -> 20 | O21: =INDEX('Points Schedule'!$H$4:$M$4, MATCH(E21, 'Points Schedule'!$H$2:$M$2, 0)) -> 45 | P21: =INDEX('Points Schedule'!$H$5:$M$5, MATCH(F21, 'Points Schedule'!$H$2:$M$2, 0)) -> 10 | Q21: =INDEX('Points Schedule'!$H$6:$M$6, MATCH(G21, 'Points Schedule'!$H$2:$M$2, 0)) -> 25 | R21: =INDEX('Points Schedule'!$H$7:$M$7, MATCH(I21, 'Points Schedule'!$H$2:$M$2, 0)) -> 10 | S21: =INDEX('Points Schedule'!$H$8:$M$8, MATCH(J21, 'Points Schedule'!$H$2:$M$2, 0)) -> 70 | T21: =INDEX('Points Schedule'!$H$9:$M$9, MATCH(K21, 'Points Schedule'!$H$2:$M$2, 0)) -> 40 | U21: =INDEX('Points Schedule'!$H$10:$M$10, MATCH(L21, 'Points Schedule'!$H$2:$M$2, 0)) -> 40 | V21: =INDEX('Points Schedule'!$H$11:$M$11, MATCH(M21, 'Points Schedule'!$H$2:$M$2, 0)) -> 90 | W21: =SUM(N21:V21) -> 350 | X21: {=INDEX(Clusters!A:A, MATCH(1, (W21>=Clusters!B:B)*(W21<=Clusters!C:C), 0))} -> 5 | Y21: 47.838276 | Z21: =Y21*1000 -> 47838.276
A22: Business Analyst | B22: Ops | C22: 63348 | D22: 3 | E22: 2 | F22: 2 | G22: 2 | H22: 1 | I22: 1 | J22: 1 | K22: 1 | L22: 1 | M22: 3 | N22: =INDEX('Points Schedule'!$H$3:$M$3, MATCH(D22, 'Points Schedule'!$H$2:$M$2, 0)) -> 30 | O22: =INDEX('Points Schedule'!$H$4:$M$4, MATCH(E22, 'Points Schedule'!$H$2:$M$2, 0)) -> 30 | P22: =INDEX('Points Schedule'!$H$5:$M$5, MATCH(F22, 'Points Schedule'!$H$2:$M$2, 0)) -> 10 | Q22: =INDEX('Points Schedule'!$H$6:$M$6, MATCH(G22, 'Points Schedule'!$H$2:$M$2, 0)) -> 50 | R22: =INDEX('Points Schedule'!$H$7:$M$7, MATCH(I22, 'Points Schedule'!$H$2:$M$2, 0)) -> 10 | S22: =INDEX('Points Schedule'!$H$8:$M$8, MATCH(J22, 'Points Schedule'!$H$2:$M$2, 0)) -> 70 | T22: =INDEX('Points Schedule'!$H$9:$M$9, MATCH(K22, 'Points Schedule'!$H$2:$M$2, 0)) -> 20 | U22: =INDEX('Points Schedule'!$H$10:$M$10, MATCH(L22, 'Points Schedule'!$H$2:$M$2, 0)) -> 40 | V22: =INDEX('Points Schedule'!$H$11:$M$11, MATCH(M22, 'Points Schedule'!$H$2:$M$2, 0)) -> 90 | W22: =SUM(N22:V22) -> 350 | X22: {=INDEX(Clusters!A:A, MATCH(1, (W22>=Clusters!B:B)*(W22<=Clusters!C:C), 0))} -> 5
A23: Peer Review Administrator, Audit | B23: Quality Assurance | C23: 56000 | D23: 3 | E23: 2 | F23: 2 | G23: 1 | H23: 1 | I23: 1 | J23: 1 | K23: 2 | L23: 2 | M23: 2 | N23: =INDEX('Points Schedule'!$H$3:$M$3, MATCH(D23, 'Points Schedule'!$H$2:$M$2, 0)) -> 30 | O23: =INDEX('Points Schedule'!$H$4:$M$4, MATCH(E23, 'Points Schedule'!$H$2:$M$2, 0)) -> 30 | P23: =INDEX('Points Schedule'!$H$5:$M$5, MATCH(F23, 'Points Schedule'!$H$2:$M$2, 0)) -> 10 | Q23: =INDEX('Points Schedule'!$H$6:$M$6, MATCH(G23, 'Points Schedule'!$H$2:$M$2, 0)) -> 25 | R23: =INDEX('Points Schedule'!$H$7:$M$7, MATCH(I23, 'Points Schedule'!$H$2:$M$2, 0)) -> 10 | S23: =INDEX('Points Schedule'!$H$8:$M$8, MATCH(J23, 'Points Schedule'!$H$2:$M$2, 0)) -> 70 | T23: =INDEX('Points Schedule'!$H$9:$M$9, MATCH(K23, 'Points Schedule'!$H$2:$M$2, 0)) -> 40 | U23: =INDEX('Points Schedule'!$H$10:$M$10, MATCH(L23, 'Points Schedule'!$H$2:$M$2, 0)) -> 80 | V23: =INDEX('Points Schedule'!$H$11:$M$11, MATCH(M23, 'Points Schedule'!$H$2:$M$2, 0)) -> 60 | W23: =SUM(N23:V23) -> 355 | X23: {=INDEX(Clusters!A:A, MATCH(1, (W23>=Clusters!B:B)*(W23<=Clusters!C:C), 0))} -> 5
A24: Peer Review Administrator, Audit | B24: Quality Assurance | C24: 54390 | D24: 3 | E24: 2 | F24: 2 | G24: 1 | H24: 1 | I24: 1 | J24: 1 | K24: 2 | L24: 2 | M24: 2 | N24: =INDEX('Points Schedule'!$H$3:$M$3, MATCH(D24, 'Points Schedule'!$H$2:$M$2, 0)) -> 30 | O24: =INDEX('Points Schedule'!$H$4:$M$4, MATCH(E24, 'Points Schedule'!$H$2:$M$2, 0)) -> 30 | P24: =INDEX('Points Schedule'!$H$5:$M$5, MATCH(F24, 'Points Schedule'!$H$2:$M$2, 0)) -> 10 | Q24: =INDEX('Points Schedule'!$H$6:$M$6, MATCH(G24, 'Points Schedule'!$H$2:$M$2, 0)) -> 25 | R24: =INDEX('Points Schedule'!$H$7:$M$7, MATCH(I24, 'Points Schedule'!$H$2:$M$2, 0)) -> 10 | S24: =INDEX('Points Schedule'!$H$8:$M$8, MATCH(J24, 'Points Schedule'!$H$2:$M$2, 0)) -> 70 | T24: =INDEX('Points Schedule'!$H$9:$M$9, MATCH(K24, 'Points Schedule'!$H$2:$M$2, 0)) -> 40 | U24: =INDEX('Points Schedule'!$H$10:$M$10, MATCH(L24, 'Points Schedule'!$H$2:$M$2, 0)) -> 80 | V24: =INDEX('Points Schedule'!$H$11:$M$11, MATCH(M24, 'Points Schedule'!$H$2:$M$2, 0)) -> 60 | W24: =SUM(N24:V24) -> 355 | X24: {=INDEX(Clusters!A:A, MATCH(1, (W24>=Clusters!B:B)*(W24<=Clusters!C:C), 0))} -> 5
A25: Peer Review Administrator, Tax | B25: Quality Assurance | C25: 58700 | D25: 3 | E25: 2 | F25: 2 | G25: 2 | H25: 1 | I25: 1 | J25: 1 | K25: 1 | L25: 2 | M25: 2 | N25: =INDEX('Points Schedule'!$H$3:$M$3, MATCH(D25, 'Points Schedule'!$H$2:$M$2, 0)) -> 30 | O25: =INDEX('Points Schedule'!$H$4:$M$4, MATCH(E25, 'Points Schedule'!$H$2:$M$2, 0)) -> 30 | P25: =INDEX('Points Schedule'!$H$5:$M$5, MATCH(F25, 'Points Schedule'!$H$2:$M$2, 0)) -> 10 | Q25: =INDEX('Points Schedule'!$H$6:$M$6, MATCH(G25, 'Points Schedule'!$H$2:$M$2, 0)) -> 50 | R25: =INDEX('Points Schedule'!$H$7:$M$7, MATCH(I25, 'Points Schedule'!$H$2:$M$2, 0)) -> 10 | S25: =INDEX('Points Schedule'!$H$8:$M$8, MATCH(J25, 'Points Schedule'!$H$2:$M$2, 0)) -> 70 | T25: =INDEX('Points Schedule'!$H$9:$M$9, MATCH(K25, 'Points Schedule'!$H$2:$M$2, 0)) -> 20 | U25: =INDEX('Points Schedule'!$H$10:$M$10, MATCH(L25, 'Points Schedule'!$H$2:$M$2, 0)) -> 80 | V25: =INDEX('Points Schedule'!$H$11:$M$11, MATCH(M25, 'Points Schedule'!$H$2:$M$2, 0)) -> 60 | W25: =SUM(N25:V25) -> 360 | X25: {=INDEX(Clusters!A:A, MATCH(1, (W25>=Clusters!B:B)*(W25<=Clusters!C:C), 0))} -> 5
A26: Information Officer | B26: Marketing | C26: 55233 | D26: 3 | E26: 1 | F26: 2 | G26: 2 | H26: 1 | I26: 2 | J26: 1 | K26: 1 | L26: 3 | M26: 1 | N26: =INDEX('Points Schedule'!$H$3:$M$3, MATCH(D26, 'Points Schedule'!$H$2:$M$2, 0)) -> 30 | O26: =INDEX('Points Schedule'!$H$4:$M$4, MATCH(E26, 'Points Schedule'!$H$2:$M$2, 0)) -> 15 | P26: =INDEX('Points Schedule'!$H$5:$M$5, MATCH(F26, 'Points Schedule'!$H$2:$M$2, 0)) -> 10 | Q26: =INDEX('Points Schedule'!$H$6:$M$6, MATCH(G26, 'Points Schedule'!$H$2:$M$2, 0)) -> 50 | R26: =INDEX('Points Schedule'!$H$7:$M$7, MATCH(I26, 'Points Schedule'!$H$2:$M$2, 0)) -> 20 | S26: =INDEX('Points Schedule'!$H$8:$M$8, MATCH(J26, 'Points Schedule'!$H$2:$M$2, 0)) -> 70 | T26: =INDEX('Points Schedule'!$H$9:$M$9, MATCH(K26, 'Points Schedule'!$H$2:$M$2, 0)) -> 20 | U26: =INDEX('Points Schedule'!$H$10:$M$10, MATCH(L26, 'Points Schedule'!$H$2:$M$2, 0)) -> 120 | V26: =INDEX('Points Schedule'!$H$11:$M$11, MATCH(M26, 'Points Schedule'!$H$2:$M$2, 0)) -> 30 | W26: =SUM(N26:V26) -> 365 | X26: {=INDEX(Clusters!A:A, MATCH(1, (W26>=Clusters!B:B)*(W26<=Clusters!C:C), 0))} -> 6
A27: Web Developer | B27: IT | C27: 59000 | D27: 3 | E27: 5 | F27: 2 | G27: 2 | H27: 1 | I27: 1 | J27: 1 | K27: 3 | L27: 1 | M27: 1 | N27: =INDEX('Points Schedule'!$H$3:$M$3, MATCH(D27, 'Points Schedule'!$H$2:$M$2, 0)) -> 30 | O27: =INDEX('Points Schedule'!$H$4:$M$4, MATCH(E27, 'Points Schedule'!$H$2:$M$2, 0)) -> 75 | P27: =INDEX('Points Schedule'!$H$5:$M$5, MATCH(F27, 'Points Schedule'!$H$2:$M$2, 0)) -> 10 | Q27: =INDEX('Points Schedule'!$H$6:$M$6, MATCH(G27, 'Points Schedule'!$H$2:$M$2, 0)) -> 50 | R27: =INDEX('Points Schedule'!$H$7:$M$7, MATCH(I27, 'Points Schedule'!$H$2:$M$2, 0)) -> 10 | S27: =INDEX('Points Schedule'!$H$8:$M$8, MATCH(J27, 'Points Schedule'!$H$2:$M$2, 0)) -> 70 | T27: =INDEX('Points Schedule'!$H$9:$M$9, MATCH(K27, 'Points Schedule'!$H$2:$M$2, 0)) -> 60 | U27: =INDEX('Points Schedule'!$H$10:$M$10, MATCH(L27, 'Points Schedule'!$H$2:$M$2, 0)) -> 40 | V27: =INDEX('Points Schedule'!$H$11:$M$11, MATCH(M27, 'Points Schedule'!$H$2:$M$2, 0)) -> 30 | W27: =SUM(N27:V27) -> 375 | X27: {=INDEX(Clusters!A:A, MATCH(1, (W27>=Clusters!B:B)*(W27<=Clusters!C:C), 0))} -> 6
A28: Communications Specialist | B28: Marketing | C28: 67040 | D28: 3 | E28: 3 | F28: 1 | G28: 1 | H28: 2 | I28: 1 | J28: 1 | K28: 2 | L28: 2 | M28: 3 | N28: =INDEX('Points Schedule'!$H$3:$M$3, MATCH(D28, 'Points Schedule'!$H$2:$M$2, 0)) -> 30 | O28: =INDEX('Points Schedule'!$H$4:$M$4, MATCH(E28, 'Points Schedule'!$H$2:$M$2, 0)) -> 45 | P28: =INDEX('Points Schedule'!$H$5:$M$5, MATCH(F28, 'Points Schedule'!$H$2:$M$2, 0)) -> 5 | Q28: =INDEX('Points Schedule'!$H$6:$M$6, MATCH(G28, 'Points Schedule'!$H$2:$M$2, 0)) -> 25 | R28: =INDEX('Points Schedule'!$H$7:$M$7, MATCH(I28, 'Points Schedule'!$H$2:$M$2, 0)) -> 10 | S28: =INDEX('Points Schedule'!$H$8:$M$8, MATCH(J28, 'Points Schedule'!$H$2:$M$2, 0)) -> 70 | T28: =INDEX('Points Schedule'!$H$9:$M$9, MATCH(K28, 'Points Schedule'!$H$2:$M$2, 0)) -> 40 | U28: =INDEX('Points Schedule'!$H$10:$M$10, MATCH(L28, 'Points Schedule'!$H$2:$M$2, 0)) -> 80 | V28: =INDEX('Points Schedule'!$H$11:$M$11, MATCH(M28, 'Points Schedule'!$H$2:$M$2, 0)) -> 90 | W28: =SUM(N28:V28) -> 395 | X28: {=INDEX(Clusters!A:A, MATCH(1, (W28>=Clusters!B:B)*(W28<=Clusters!C:C), 0))} -> 6 | Y28: 57.876923 | Z28: =Y28*1000 -> 57876.923
A29: Senior Accountant | B29: Ops | C29: 51082 | D29: 3 | E29: 2 | F29: 2 | G29: 2 | H29: 1 | I29: 3 | J29: 2 | K29: 1 | L29: 1 | M29: 2 | N29: =INDEX('Points Schedule'!$H$3:$M$3, MATCH(D29, 'Points Schedule'!$H$2:$M$2, 0)) -> 30 | O29: =INDEX('Points Schedule'!$H$4:$M$4, MATCH(E29, 'Points Schedule'!$H$2:$M$2, 0)) -> 30 | P29: =INDEX('Points Schedule'!$H$5:$M$5, MATCH(F29, 'Points Schedule'!$H$2:$M$2, 0)) -> 10 | Q29: =INDEX('Points Schedule'!$H$6:$M$6, MATCH(G29, 'Points Schedule'!$H$2:$M$2, 0)) -> 50 | R29: =INDEX('Points Schedule'!$H$7:$M$7, MATCH(I29, 'Points Schedule'!$H$2:$M$2, 0)) -> 30 | S29: =INDEX('Points Schedule'!$H$8:$M$8, MATCH(J29, 'Points Schedule'!$H$2:$M$2, 0)) -> 140 | T29: =INDEX('Points Schedule'!$H$9:$M$9, MATCH(K29, 'Points Schedule'!$H$2:$M$2, 0)) -> 20 | U29: =INDEX('Points Schedule'!$H$10:$M$10, MATCH(L29, 'Points Schedule'!$H$2:$M$2, 0)) -> 40 | V29: =INDEX('Points Schedule'!$H$11:$M$11, MATCH(M29, 'Points Schedule'!$H$2:$M$2, 0)) -> 60 | W29: =SUM(N29:V29) -> 410 | X29: {=INDEX(Clusters!A:A, MATCH(1, (W29>=Clusters!B:B)*(W29<=Clusters!C:C), 0))} -> 6 | Y29: 68.414634 | Z29: =Y29*1000 -> 68414.634
A30: Coordinator, Audit and Assurance | B30: Quality Assurance | C30: 64755 | D30: 3 | E30: 3 | F30: 2 | G30: 2 | H30: 2 | I30: 1 | J30: 1 | K30: 2 | L30: 2 | M30: 3 | N30: =INDEX('Points Schedule'!$H$3:$M$3, MATCH(D30, 'Points Schedule'!$H$2:$M$2, 0)) -> 30 | O30: =INDEX('Points Schedule'!$H$4:$M$4, MATCH(E30, 'Points Schedule'!$H$2:$M$2, 0)) -> 45 | P30: =INDEX('Points Schedule'!$H$5:$M$5, MATCH(F30, 'Points Schedule'!$H$2:$M$2, 0)) -> 10 | Q30: =INDEX('Points Schedule'!$H$6:$M$6, MATCH(G30, 'Points Schedule'!$H$2:$M$2, 0)) -> 50 | R30: =INDEX('Points Schedule'!$H$7:$M$7, MATCH(I30, 'Points Schedule'!$H$2:$M$2, 0)) -> 10 | S30: =INDEX('Points Schedule'!$H$8:$M$8, MATCH(J30, 'Points Schedule'!$H$2:$M$2, 0)) -> 70 | T30: =INDEX('Points Schedule'!$H$9:$M$9, MATCH(K30, 'Points Schedule'!$H$2:$M$2, 0)) -> 40 | U30: =INDEX('Points Schedule'!$H$10:$M$10, MATCH(L30, 'Points Schedule'!$H$2:$M$2, 0)) -> 80 | V30: =INDEX('Points Schedule'!$H$11:$M$11, MATCH(M30, 'Points Schedule'!$H$2:$M$2, 0)) -> 90 | W30: =SUM(N30:V30) -> 425 | X30: {=INDEX(Clusters!A:A, MATCH(1, (W30>=Clusters!B:B)*(W30<=Clusters!C:C), 0))} -> 7 | Y30: 70.516216 | Z30: =Y30*1000 -> 70516.216
A31: Marketing Coordinator | B31: Marketing | C31: 47375 | D31: 3 | E31: 3 | F31: 2 | G31: 2 | H31: 4 | I31: 3 | J31: 1 | K31: 3 | L31: 2 | M31: 3 | N31: =INDEX('Points Schedule'!$H$3:$M$3, MATCH(D31, 'Points Schedule'!$H$2:$M$2, 0)) -> 30 | O31: =INDEX('Points Schedule'!$H$4:$M$4, MATCH(E31, 'Points Schedule'!$H$2:$M$2, 0)) -> 45 | P31: =INDEX('Points Schedule'!$H$5:$M$5, MATCH(F31, 'Points Schedule'!$H$2:$M$2, 0)) -> 10 | Q31: =INDEX('Points Schedule'!$H$6:$M$6, MATCH(G31, 'Points Schedule'!$H$2:$M$2, 0)) -> 50 | R31: =INDEX('Points Schedule'!$H$7:$M$7, MATCH(I31, 'Points Schedule'!$H$2:$M$2, 0)) -> 30 | S31: =INDEX('Points Schedule'!$H$8:$M$8, MATCH(J31, 'Points Schedule'!$H$2:$M$2, 0)) -> 70 | T31: =INDEX('Points Schedule'!$H$9:$M$9, MATCH(K31, 'Points Schedule'!$H$2:$M$2, 0)) -> 60 | U31: =INDEX('Points Schedule'!$H$10:$M$10, MATCH(L31, 'Points Schedule'!$H$2:$M$2, 0)) -> 80 | V31: =INDEX('Points Schedule'!$H$11:$M$11, MATCH(M31, 'Points Schedule'!$H$2:$M$2, 0)) -> 90 | W31: =SUM(N31:V31) -> 465 | X31: {=INDEX(Clusters!A:A, MATCH(1, (W31>=Clusters!B:B)*(W31<=Clusters!C:C), 0))} -> 7 | Y31: 47.849333 | Z31: =Y31*1000 -> 47849.333
A32: Coordinator, Professional Programs | B32: Continuing Education | C32: 53042 | D32: 4 | E32: 3 | F32: 4 | G32: 2 | H32: 2 | I32: 1 | J32: 2 | K32: 4 | L32: 2 | M32: 2 | N32: =INDEX('Points Schedule'!$H$3:$M$3, MATCH(D32, 'Points Schedule'!$H$2:$M$2, 0)) -> 40 | O32: =INDEX('Points Schedule'!$H$4:$M$4, MATCH(E32, 'Points Schedule'!$H$2:$M$2, 0)) -> 45 | P32: =INDEX('Points Schedule'!$H$5:$M$5, MATCH(F32, 'Points Schedule'!$H$2:$M$2, 0)) -> 20 | Q32: =INDEX('Points Schedule'!$H$6:$M$6, MATCH(G32, 'Points Schedule'!$H$2:$M$2, 0)) -> 50 | R32: =INDEX('Points Schedule'!$H$7:$M$7, MATCH(I32, 'Points Schedule'!$H$2:$M$2, 0)) -> 10 | S32: =INDEX('Points Schedule'!$H$8:$M$8, MATCH(J32, 'Points Schedule'!$H$2:$M$2, 0)) -> 140 | T32: =INDEX('Points Schedule'!$H$9:$M$9, MATCH(K32, 'Points Schedule'!$H$2:$M$2, 0)) -> 80 | U32: =INDEX('Points Schedule'!$H$10:$M$10, MATCH(L32, 'Points Schedule'!$H$2:$M$2, 0)) -> 80 | V32: =INDEX('Points Schedule'!$H$11:$M$11, MATCH(M32, 'Points Schedule'!$H$2:$M$2, 0)) -> 60 | W32: =SUM(N32:V32) -> 525 | X32: {=INDEX(Clusters!A:A, MATCH(1, (W32>=Clusters!B:B)*(W32<=Clusters!C:C), 0))} -> 8
A33: Manager Conferences and Event Planning | B33: Continuing Education | C33: 72180 | D33: 2 | E33: 2 | F33: 4 | G33: 1 | H33: 4 | I33: 2 | J33: 3 | K33: 3 | L33: 2 | M33: 2 | N33: =INDEX('Points Schedule'!$H$3:$M$3, MATCH(D33, 'Points Schedule'!$H$2:$M$2, 0)) -> 20 | O33: =INDEX('Points Schedule'!$H$4:$M$4, MATCH(E33, 'Points Schedule'!$H$2:$M$2, 0)) -> 30 | P33: =INDEX('Points Schedule'!$H$5:$M$5, MATCH(F33, 'Points Schedule'!$H$2:$M$2, 0)) -> 20 | Q33: =INDEX('Points Schedule'!$H$6:$M$6, MATCH(G33, 'Points Schedule'!$H$2:$M$2, 0)) -> 25 | R33: =INDEX('Points Schedule'!$H$7:$M$7, MATCH(I33, 'Points Schedule'!$H$2:$M$2, 0)) -> 20 | S33: =INDEX('Points Schedule'!$H$8:$M$8, MATCH(J33, 'Points Schedule'!$H$2:$M$2, 0)) -> 210 | T33: =INDEX('Points Schedule'!$H$9:$M$9, MATCH(K33, 'Points Schedule'!$H$2:$M$2, 0)) -> 60 | U33: =INDEX('Points Schedule'!$H$10:$M$10, MATCH(L33, 'Points Schedule'!$H$2:$M$2, 0)) -> 80 | V33: =INDEX('Points Schedule'!$H$11:$M$11, MATCH(M33, 'Points Schedule'!$H$2:$M$2, 0)) -> 60 | W33: =SUM(N33:V33) -> 525 | X33: {=INDEX(Clusters!A:A, MATCH(1, (W33>=Clusters!B:B)*(W33<=Clusters!C:C), 0))} -> 8 | Y33: 69.642857 | Z33: =Y33*1000 -> 69642.857
A34: Manager, Workforce Recruitment | B34: Marketing | C34: 83828 | D34: 3 | E34: 5 | F34: 3 | G34: 3 | H34: 3 | I34: 2 | J34: 1 | K34: 4 | L34: 3 | M34: 2 | N34: =INDEX('Points Schedule'!$H$3:$M$3, MATCH(D34, 'Points Schedule'!$H$2:$M$2, 0)) -> 30 | O34: =INDEX('Points Schedule'!$H$4:$M$4, MATCH(E34, 'Points Schedule'!$H$2:$M$2, 0)) -> 75 | P34: =INDEX('Points Schedule'!$H$5:$M$5, MATCH(F34, 'Points Schedule'!$H$2:$M$2, 0)) -> 15 | Q34: =INDEX('Points Schedule'!$H$6:$M$6, MATCH(G34, 'Points Schedule'!$H$2:$M$2, 0)) -> 75 | R34: =INDEX('Points Schedule'!$H$7:$M$7, MATCH(I34, 'Points Schedule'!$H$2:$M$2, 0)) -> 20 | S34: =INDEX('Points Schedule'!$H$8:$M$8, MATCH(J34, 'Points Schedule'!$H$2:$M$2, 0)) -> 70 | T34: =INDEX('Points Schedule'!$H$9:$M$9, MATCH(K34, 'Points Schedule'!$H$2:$M$2, 0)) -> 80 | U34: =INDEX('Points Schedule'!$H$10:$M$10, MATCH(L34, 'Points Schedule'!$H$2:$M$2, 0)) -> 120 | V34: =INDEX('Points Schedule'!$H$11:$M$11, MATCH(M34, 'Points Schedule'!$H$2:$M$2, 0)) -> 60 | W34: =SUM(N34:V34) -> 545 | X34: {=INDEX(Clusters!A:A, MATCH(1, (W34>=Clusters!B:B)*(W34<=Clusters!C:C), 0))} -> 8
A35: Manager, Education Outreach | B35: Marketing | C35: 81247 | D35: 3 | E35: 2 | F35: 2 | G35: 3 | H35: 3 | I35: 2 | J35: 2 | K35: 4 | L35: 3 | M35: 2 | N35: =INDEX('Points Schedule'!$H$3:$M$3, MATCH(D35, 'Points Schedule'!$H$2:$M$2, 0)) -> 30 | O35: =INDEX('Points Schedule'!$H$4:$M$4, MATCH(E35, 'Points Schedule'!$H$2:$M$2, 0)) -> 30 | P35: =INDEX('Points Schedule'!$H$5:$M$5, MATCH(F35, 'Points Schedule'!$H$2:$M$2, 0)) -> 10 | Q35: =INDEX('Points Schedule'!$H$6:$M$6, MATCH(G35, 'Points Schedule'!$H$2:$M$2, 0)) -> 75 | R35: =INDEX('Points Schedule'!$H$7:$M$7, MATCH(I35, 'Points Schedule'!$H$2:$M$2, 0)) -> 20 | S35: =INDEX('Points Schedule'!$H$8:$M$8, MATCH(J35, 'Points Schedule'!$H$2:$M$2, 0)) -> 140 | T35: =INDEX('Points Schedule'!$H$9:$M$9, MATCH(K35, 'Points Schedule'!$H$2:$M$2, 0)) -> 80 | U35: =INDEX('Points Schedule'!$H$10:$M$10, MATCH(L35, 'Points Schedule'!$H$2:$M$2, 0)) -> 120 | V35: =INDEX('Points Schedule'!$H$11:$M$11, MATCH(M35, 'Points Schedule'!$H$2:$M$2, 0)) -> 60 | W35: =SUM(N35:V35) -> 565 | X35: {=INDEX(Clusters!A:A, MATCH(1, (W35>=Clusters!B:B)*(W35<=Clusters!C:C), 0))} -> 8
A36: Manager Finance and Administration | B36: Ops | C36: 69733 | D36: 3 | E36: 3 | F36: 3 | G36: 3 | H36: 5 | I36: 3 | J36: 2 | K36: 3 | L36: 2 | M36: 3 | N36: =INDEX('Points Schedule'!$H$3:$M$3, MATCH(D36, 'Points Schedule'!$H$2:$M$2, 0)) -> 30 | O36: =INDEX('Points Schedule'!$H$4:$M$4, MATCH(E36, 'Points Schedule'!$H$2:$M$2, 0)) -> 45 | P36: =INDEX('Points Schedule'!$H$5:$M$5, MATCH(F36, 'Points Schedule'!$H$2:$M$2, 0)) -> 15 | Q36: =INDEX('Points Schedule'!$H$6:$M$6, MATCH(G36, 'Points Schedule'!$H$2:$M$2, 0)) -> 75 | R36: =INDEX('Points Schedule'!$H$7:$M$7, MATCH(I36, 'Points Schedule'!$H$2:$M$2, 0)) -> 30 | S36: =INDEX('Points Schedule'!$H$8:$M$8, MATCH(J36, 'Points Schedule'!$H$2:$M$2, 0)) -> 140 | T36: =INDEX('Points Schedule'!$H$9:$M$9, MATCH(K36, 'Points Schedule'!$H$2:$M$2, 0)) -> 60 | U36: =INDEX('Points Schedule'!$H$10:$M$10, MATCH(L36, 'Points Schedule'!$H$2:$M$2, 0)) -> 80 | V36: =INDEX('Points Schedule'!$H$11:$M$11, MATCH(M36, 'Points Schedule'!$H$2:$M$2, 0)) -> 90 | W36: =SUM(N36:V36) -> 565 | X36: {=INDEX(Clusters!A:A, MATCH(1, (W36>=Clusters!B:B)*(W36<=Clusters!C:C), 0))} -> 8 | Y36: 85.162369 | Z36: =Y36*1000 -> 85162.369
A37: Manager, Executive Office | B37: Exec | C37: 71707 | D37: 3 | E37: 3 | F37: 4 | G37: 3 | H37: 4 | I37: 3 | J37: 2 | K37: 5 | L37: 3 | M37: 3 | N37: =INDEX('Points Schedule'!$H$3:$M$3, MATCH(D37, 'Points Schedule'!$H$2:$M$2, 0)) -> 30 | O37: =INDEX('Points Schedule'!$H$4:$M$4, MATCH(E37, 'Points Schedule'!$H$2:$M$2, 0)) -> 45 | P37: =INDEX('Points Schedule'!$H$5:$M$5, MATCH(F37, 'Points Schedule'!$H$2:$M$2, 0)) -> 20 | Q37: =INDEX('Points Schedule'!$H$6:$M$6, MATCH(G37, 'Points Schedule'!$H$2:$M$2, 0)) -> 75 | R37: =INDEX('Points Schedule'!$H$7:$M$7, MATCH(I37, 'Points Schedule'!$H$2:$M$2, 0)) -> 30 | S37: =INDEX('Points Schedule'!$H$8:$M$8, MATCH(J37, 'Points Schedule'!$H$2:$M$2, 0)) -> 140 | T37: =INDEX('Points Schedule'!$H$9:$M$9, MATCH(K37, 'Points Schedule'!$H$2:$M$2, 0)) -> 100 | U37: =INDEX('Points Schedule'!$H$10:$M$10, MATCH(L37, 'Points Schedule'!$H$2:$M$2, 0)) -> 120 | V37: =INDEX('Points Schedule'!$H$11:$M$11, MATCH(M37, 'Points Schedule'!$H$2:$M$2, 0)) -> 90 | W37: =SUM(N37:V37) -> 650 | X37: {=INDEX(Clusters!A:A, MATCH(1, (W37>=Clusters!B:B)*(W37<=Clusters!C:C), 0))} -> 9
A38: Manager, Audit and Assurance | B38: Quality Assurance | C38: 84980 | D38: 4 | E38: 5 | F38: 3 | G38: 3 | H38: 5 | I38: 1 | J38: 3 | K38: 3 | L38: 2 | M38: 3 | N38: =INDEX('Points Schedule'!$H$3:$M$3, MATCH(D38, 'Points Schedule'!$H$2:$M$2, 0)) -> 40 | O38: =INDEX('Points Schedule'!$H$4:$M$4, MATCH(E38, 'Points Schedule'!$H$2:$M$2, 0)) -> 75 | P38: =INDEX('Points Schedule'!$H$5:$M$5, MATCH(F38, 'Points Schedule'!$H$2:$M$2, 0)) -> 15 | Q38: =INDEX('Points Schedule'!$H$6:$M$6, MATCH(G38, 'Points Schedule'!$H$2:$M$2, 0)) -> 75 | R38: =INDEX('Points Schedule'!$H$7:$M$7, MATCH(I38, 'Points Schedule'!$H$2:$M$2, 0)) -> 10 | S38: =INDEX('Points Schedule'!$H$8:$M$8, MATCH(J38, 'Points Schedule'!$H$2:$M$2, 0)) -> 210 | T38: =INDEX('Points Schedule'!$H$9:$M$9, MATCH(K38, 'Points Schedule'!$H$2:$M$2, 0)) -> 60 | U38: =INDEX('Points Schedule'!$H$10:$M$10, MATCH(L38, 'Points Schedule'!$H$2:$M$2, 0)) -> 80 | V38: =INDEX('Points Schedule'!$H$11:$M$11, MATCH(M38, 'Points Schedule'!$H$2:$M$2, 0)) -> 90 | W38: =SUM(N38:V38) -> 655 | X38: {=INDEX(Clusters!A:A, MATCH(1, (W38>=Clusters!B:B)*(W38<=Clusters!C:C), 0))} -> 9
A39: Manager, Tax Quality | B39: Quality Assurance | C39: 70000 | D39: 4 | E39: 5 | F39: 3 | G39: 3 | H39: 5 | I39: 1 | J39: 3 | K39: 3 | L39: 2 | M39: 3 | N39: =INDEX('Points Schedule'!$H$3:$M$3, MATCH(D39, 'Points Schedule'!$H$2:$M$2, 0)) -> 40 | O39: =INDEX('Points Schedule'!$H$4:$M$4, MATCH(E39, 'Points Schedule'!$H$2:$M$2, 0)) -> 75 | P39: =INDEX('Points Schedule'!$H$5:$M$5, MATCH(F39, 'Points Schedule'!$H$2:$M$2, 0)) -> 15 | Q39: =INDEX('Points Schedule'!$H$6:$M$6, MATCH(G39, 'Points Schedule'!$H$2:$M$2, 0)) -> 75 | R39: =INDEX('Points Schedule'!$H$7:$M$7, MATCH(I39, 'Points Schedule'!$H$2:$M$2, 0)) -> 10 | S39: =INDEX('Points Schedule'!$H$8:$M$8, MATCH(J39, 'Points Schedule'!$H$2:$M$2, 0)) -> 210 | T39: =INDEX('Points Schedule'!$H$9:$M$9, MATCH(K39, 'Points Schedule'!$H$2:$M$2, 0)) -> 60 | U39: =INDEX('Points Schedule'!$H$10:$M$10, MATCH(L39, 'Points Schedule'!$H$2:$M$2, 0)) -> 80 | V39: =INDEX('Points Schedule'!$H$11:$M$11, MATCH(M39, 'Points Schedule'!$H$2:$M$2, 0)) -> 90 | W39: =SUM(N39:V39) -> 655 | X39: {=INDEX(Clusters!A:A, MATCH(1, (W39>=Clusters!B:B)*(W39<=Clusters!C:C), 0))} -> 9
A40: Manager, Member Services Centre | B40: Ops | C40: 95151 | D40: 4 | E40: 3 | F40: 4 | G40: 3 | H40: 5 | I40: 3 | J40: 3 | K40: 4 | L40: 2 | M40: 3 | N40: =INDEX('Points Schedule'!$H$3:$M$3, MATCH(D40, 'Points Schedule'!$H$2:$M$2, 0)) -> 40 | O40: =INDEX('Points Schedule'!$H$4:$M$4, MATCH(E40, 'Points Schedule'!$H$2:$M$2, 0)) -> 45 | P40: =INDEX('Points Schedule'!$H$5:$M$5, MATCH(F40, 'Points Schedule'!$H$2:$M$2, 0)) -> 20 | Q40: =INDEX('Points Schedule'!$H$6:$M$6, MATCH(G40, 'Points Schedule'!$H$2:$M$2, 0)) -> 75 | R40: =INDEX('Points Schedule'!$H$7:$M$7, MATCH(I40, 'Points Schedule'!$H$2:$M$2, 0)) -> 30 | S40: =INDEX('Points Schedule'!$H$8:$M$8, MATCH(J40, 'Points Schedule'!$H$2:$M$2, 0)) -> 210 | T40: =INDEX('Points Schedule'!$H$9:$M$9, MATCH(K40, 'Points Schedule'!$H$2:$M$2, 0)) -> 80 | U40: =INDEX('Points Schedule'!$H$10:$M$10, MATCH(L40, 'Points Schedule'!$H$2:$M$2, 0)) -> 80 | V40: =INDEX('Points Schedule'!$H$11:$M$11, MATCH(M40, 'Points Schedule'!$H$2:$M$2, 0)) -> 90 | W40: =SUM(N40:V40) -> 670 | X40: {=INDEX(Clusters!A:A, MATCH(1, (W40>=Clusters!B:B)*(W40<=Clusters!C:C), 0))} -> 9
...

Sheet Benchmarks
A1: Position Title | B1: Department | C1: 2007 Salary | D1: Total Points | E1: Cluster | F1: Benchmark
A2: =Data!A4 -> Receptionist | B2: =Data!B4 -> Ops | C2: =Data!C4 -> 44526 | D2: =Data!W4 -> 260 | E2: =Data!X4 -> 2 | F2: =Data!Z4 -> 35287.9
A3: =Data!A3 -> Administrative Clerk | B3: =Data!B3 -> Quality Assurance | C3: =Data!C3 -> 36260 | D3: =Data!W3 -> 255 | E3: =Data!X3 -> 1 | F3: =Data!Z3 -> 38372.611
A4: =Data!A5 -> Administrative Clerk | B4: =Data!B5 -> Ops | C4: =Data!C5 -> 36113 | D4: =Data!W5 -> 265 | E4: =Data!X5 -> 2 | F4: =Data!Z5 -> 38372.611
A5: =Data!A6 -> Administrative Clerk | B5: =Data!B6 -> Ops | C5: =Data!C6 -> 32008 | D5: =Data!W6 -> 265 | E5: =Data!X6 -> 2 | F5: =Data!Z6 -> 38372.611
A6: =Data!A16 -> Administrative Clerk/mailroom clerk | B6: =Data!B16 -> Ops | C6: =Data!C16 -> 40429 | D6: =Data!W16 -> 310 | E6: =Data!X16 -> 4 | F6: =Data!Z16 -> 39200.926
A7: =Data!A14 -> Junior Accountant | B7: =Data!B14 -> Ops | C7: =Data!C14 -> 32810 | D7: =Data!W14 -> 295 | E7: =Data!X14 -> 4 | F7: =Data!Z14 -> 44119.737
A8: =Data!A11 -> Secretary (Director Continuing Education) | B8: =Data!B11 -> Continuing Education | C8: =Data!C11 -> 43898 | D8: =Data!W11 -> 285 | E8: =Data!X11 -> 3 | F8: =Data!Z11 -> 47838.276
A9: =Data!A21 -> Secretary (Director Operations) | B9: =Data!B21 -> Ops | C9: =Data!C21 -> 49508 | D9: =Data!W21 -> 350 | E9: =Data!X21 -> 5 | F9: =Data!Z21 -> 47838.276
A10: =Data!A31 -> Marketing Coordinator | B10: =Data!B31 -> Marketing | C10: =Data!C31 -> 47375 | D10: =Data!W31 -> 465 | E10: =Data!X31 -> 7 | F10: =Data!Z31 -> 47849.333
A11: =Data!A7 -> Meetings and District Programs Coordinator | B11: =Data!B7 -> Continuing Education | C11: =Data!C7 -> 42908 | D11: =Data!W7 -> 280 | E11: =Data!X7 -> 3 | F11: =Data!Z7 -> 50257.143
A12: =Data!A9 -> Seminar Coordinator | B12: =Data!B9 -> Continuing Education | C12: =Data!C9 -> 38513 | D12: =Data!W9 -> 280 | E12: =Data!X9 -> 3 | F12: =Data!Z9 -> 50257.143
A13: =Data!A10 -> Seminar Coordinator | B13: =Data!B10 -> Continuing Education | C13: =Data!C10 -> 37370 | D13: =Data!W10 -> 280 | E13: =Data!X10 -> 3 | F13: =Data!Z10 -> 50257.143
A14: =Data!A17 -> Accountant | B14: =Data!B17 -> Ops | C14: =Data!C17 -> 41530 | D14: =Data!W17 -> 330 | E14: =Data!X17 -> 5 | F14: =Data!Z17 -> 53229.843
A15: =Data!A13 -> Administrative Assistant, Exec Office | B15: =Data!B13 -> Exec | C15: =Data!C13 -> 37258 | D15: =Data!W13 -> 290 | E15: =Data!X13 -> 4 | F15: =Data!Z13 -> 55492.47
A16: =Data!A28 -> Communications Specialist | B16: =Data!B28 -> Marketing | C16: =Data!C28 -> 67040 | D16: =Data!W28 -> 395 | E16: =Data!X28 -> 6 | F16: =Data!Z28 -> 57876.923
A17: =Data!A29 -> Senior Accountant | B17: =Data!B29 -> Ops | C17: =Data!C29 -> 51082 | D17: =Data!W29 -> 410 | E17: =Data!X29 -> 6 | F17: =Data!Z29 -> 68414.634
A18: =Data!A33 -> Manager Conferences and Event Planning | B18: =Data!B33 -> Continuing Education | C18: =Data!C33 -> 72180 | D18: =Data!W33 -> 525 | E18: =Data!X33 -> 8 | F18: =Data!Z33 -> 69642.857
A19: =Data!A30 -> Coordinator, Audit and Assurance | B19: =Data!B30 -> Quality Assurance | C19: =Data!C30 -> 64755 | D19: =Data!W30 -> 425 | E19: =Data!X30 -> 7 | F19: =Data!Z30 -> 70516.216
A20: =Data!A36 -> Manager Finance and Administration | B20: =Data!B36 -> Ops | C20: =Data!C36 -> 69733 | D20: =Data!W36 -> 565 | E20: =Data!X36 -> 8 | F20: =Data!Z36 -> 85162.369
A21: =Data!A41 -> Director, IT | B21: =Data!B41 -> IT | C21: =Data!C41 -> 101981 | D21: =Data!W41 -> 685 | E21: =Data!X41 -> 9 | F21: =Data!Z41 -> 150078.79
A22: =Data!A44 -> Director, Marketing and Communications | B22: =Data!B44 -> Marketing | C22: =Data!C44 -> 118571 | D22: =Data!W44 -> 820 | E22: =Data!X44 -> 10 | F22: =Data!Z44 -> 178075
A23: =Data!A46 -> Executive Director | B23: =Data!B46 -> Exec | C23: =Data!C46 -> 171619 | D23: =Data!W46 -> 985 | E23: =Data!X46 -> 11 | F23: =Data!Z46 -> 265654.84
A24: =Data!A8 -> Circulation Technician & Receptionist | B24: =Data!B8 -> Ops | C24: =Data!C8 -> 46481 | D24: =Data!W8 -> 280 | E24: =Data!X8 -> 3
A25: =Data!A12 -> Junior Systems Administrator | B25: =Data!B12 -> IT | C25: =Data!C12 -> 41500 | D25: =Data!W12 -> 290 | E25: =Data!X12 -> 4
A26: =Data!A15 -> Business Research Coordinator | B26: =Data!B15 -> Ops | C26: =Data!C15 -> 58000 | D26: =Data!W15 -> 295 | E26: =Data!X15 -> 4
A27: =Data!A18 -> Programmer | B27: =Data!B18 -> IT | C27: =Data!C18 -> 77289 | D27: =Data!W18 -> 335 | E27: =Data!X18 -> 5
A28: =Data!A19 -> Career Consultant | B28: =Data!B19 -> Ops | C28: =Data!C19 -> 68700 | D28: =Data!W19 -> 340 | E28: =Data!X19 -> 5
A29: =Data!A20 -> Associate Coordinator, Professional Programs | B29: =Data!B20 -> Continuing Education | C29: =Data!C20 -> 39104 | D29: =Data!W20 -> 345 | E29: =Data!X20 -> 5
A30: =Data!A22 -> Business Analyst | B30: =Data!B22 -> Ops | C30: =Data!C22 -> 63348 | D30: =Data!W22 -> 350 | E30: =Data!X22 -> 5
A31: =Data!A23 -> Peer Review Administrator, Audit | B31: =Data!B23 -> Quality Assurance | C31: =Data!C23 -> 56000 | D31: =Data!W23 -> 355 | E31: =Data!X23 -> 5
A32: =Data!A24 -> Peer Review Administrator, Audit | B32: =Data!B24 -> Quality Assurance | C32: =Data!C24 -> 54390 | D32: =Data!W24 -> 355 | E32: =Data!X24 -> 5
A33: =Data!A25 -> Peer Review Administrator, Tax | B33: =Data!B25 -> Quality Assurance | C33: =Data!C25 -> 58700 | D33: =Data!W25 -> 360 | E33: =Data!X25 -> 5
A34: =Data!A26 -> Information Officer | B34: =Data!B26 -> Marketing | C34: =Data!C26 -> 55233 | D34: =Data!W26 -> 365 | E34: =Data!X26 -> 6
A35: =Data!A27 -> Web Developer | B35: =Data!B27 -> IT | C35: =Data!C27 -> 59000 | D35: =Data!W27 -> 375 | E35: =Data!X27 -> 6
A36: =Data!A32 -> Coordinator, Professional Programs | B36: =Data!B32 -> Continuing Education | C36: =Data!C32 -> 53042 | D36: =Data!W32 -> 525 | E36: =Data!X32 -> 8
A37: =Data!A34 -> Manager, Workforce Recruitment | B37: =Data!B34 -> Marketing | C37: =Data!C34 -> 83828 | D37: =Data!W34 -> 545 | E37: =Data!X34 -> 8
A38: =Data!A35 -> Manager, Education Outreach | B38: =Data!B35 -> Marketing | C38: =Data!C35 -> 81247 | D38: =Data!W35 -> 565 | E38: =Data!X35 -> 8
A39: =Data!A37 -> Manager, Executive Office | B39: =Data!B37 -> Exec | C39: =Data!C37 -> 71707 | D39: =Data!W37 -> 650 | E39: =Data!X37 -> 9
A40: =Data!A38 -> Manager, Audit and Assurance | B40: =Data!B38 -> Quality Assurance | C40: =Data!C38 -> 84980 | D40: =Data!W38 -> 655 | E40: =Data!X38 -> 9
...

Sheet Benchmark-Points Regression
A1: SUMMARY OUTPUT | N1: Position Title | O1: Department | P1: Total Points | Q1: Benchmark
N2: =Benchmarks!A2 -> Receptionist | O2: =Benchmarks!B2 -> Ops | P2: =Benchmarks!D2 -> 260 | Q2: =Benchmarks!F2 -> 35287.9
A3: Regression Statistics | N3: =Benchmarks!A3 -> Administrative Clerk | O3: =Benchmarks!B3 -> Quality Assurance | P3: =Benchmarks!D3 -> 255 | Q3: =Benchmarks!F3 -> 38372.611
A4: Multiple R | B4: 0.95116683 | N4: =Benchmarks!A4 -> Administrative Clerk | O4: =Benchmarks!B4 -> Ops | P4: =Benchmarks!D4 -> 265 | Q4: =Benchmarks!F4 -> 38372.611
A5: R Square | B5: 0.90471834 | N5: =Benchmarks!A5 -> Administrative Clerk | O5: =Benchmarks!B5 -> Ops | P5: =Benchmarks!D5 -> 265 | Q5: =Benchmarks!F5 -> 38372.611
A6: Adjusted R Square | B6: 0.89995426 | N6: =Benchmarks!A6 -> Administrative Clerk/mailroom clerk | O6: =Benchmarks!B6 -> Ops | P6: =Benchmarks!D6 -> 310 | Q6: =Benchmarks!F6 -> 39200.926
A7: Standard Error | B7: 17682.486 | N7: =Benchmarks!A7 -> Junior Accountant | O7: =Benchmarks!B7 -> Ops | P7: =Benchmarks!D7 -> 295 | Q7: =Benchmarks!F7 -> 44119.737
A8: Observations | B8: 22 | N8: =Benchmarks!A8 -> Secretary (Director Continuing Education) | O8: =Benchmarks!B8 -> Continuing Education | P8: =Benchmarks!D8 -> 285 | Q8: =Benchmarks!F8 -> 47838.276
N9: =Benchmarks!A9 -> Secretary (Director Operations) | O9: =Benchmarks!B9 -> Ops | P9: =Benchmarks!D9 -> 350 | Q9: =Benchmarks!F9 -> 47838.276
A10: ANOVA | N10: =Benchmarks!A10 -> Marketing Coordinator | O10: =Benchmarks!B10 -> Marketing | P10: =Benchmarks!D10 -> 465 | Q10: =Benchmarks!F10 -> 47849.333
B11: df | C11: SS | D11: MS | E11: F | F11: Significance F | N11: =Benchmarks!A11 -> Meetings and District Programs Coordinator | O11: =Benchmarks!B11 -> Continuing Education | P11: =Benchmarks!D11 -> 280 | Q11: =Benchmarks!F11 -> 50257.143
A12: Regression | B12: 1 | C12: 5.9377338e+10 | D12: 5.9377338e+10 | E12: 189.90399 | F12: 1.1370456e-11 | N12: =Benchmarks!A12 -> Seminar Coordinator | O12: =Benchmarks!B12 -> Continuing Education | P12: =Benchmarks!D12 -> 280 | Q12: =Benchmarks!F12 -> 50257.143
A13: Residual | B13: 20 | C13: 6.253406e+09 | D13: 3.126703e+08 | N13: =Benchmarks!A13 -> Seminar Coordinator | O13: =Benchmarks!B13 -> Continuing Education | P13: =Benchmarks!D13 -> 280 | Q13: =Benchmarks!F13 -> 50257.143
A14: Total | B14: 21 | C14: 6.5630744e+10 | N14: =Benchmarks!A14 -> Accountant | O14: =Benchmarks!B14 -> Ops | P14: =Benchmarks!D14 -> 330 | Q14: =Benchmarks!F14 -> 53229.843
N15: =Benchmarks!A15 -> Administrative Assistant, Exec Office | O15: =Benchmarks!B15 -> Exec | P15: =Benchmarks!D15 -> 290 | Q15: =Benchmarks!F15 -> 55492.47
B16: Coefficients | C16: Standard Error | D16: t Stat | E16: P-value | F16: Lower 95% | G16: Upper 95% | H16: Lower 95.0% | I16: Upper 95.0% | N16: =Benchmarks!A16 -> Communications Specialist | O16: =Benchmarks!B16 -> Marketing | P16: =Benchmarks!D16 -> 395 | Q16: =Benchmarks!F16 -> 57876.923
A17: Intercept | B17: -38573.493 | C17: 8859.9013 | D17: -4.3537159 | E17: 0.00030773095 | F17: -57054.924 | G17: -20092.063 | H17: -57054.924 | I17: -20092.063 | N17: =Benchmarks!A17 -> Senior Accountant | O17: =Benchmarks!B17 -> Ops | P17: =Benchmarks!D17 -> 410 | Q17: =Benchmarks!F17 -> 68414.634
A18: Total Points | B18: 269.4883 | C18: 19.555678 | D18: 13.780566 | E18: 1.1370456e-11 | F18: 228.69587 | G18: 310.28073 | H18: 228.69587 | I18: 310.28073 | N18: =Benchmarks!A18 -> Manager Conferences and Event Planning | O18: =Benchmarks!B18 -> Continuing Education | P18: =Benchmarks!D18 -> 525 | Q18: =Benchmarks!F18 -> 69642.857
N19: =Benchmarks!A19 -> Coordinator, Audit and Assurance | O19: =Benchmarks!B19 -> Quality Assurance | P19: =Benchmarks!D19 -> 425 | Q19: =Benchmarks!F19 -> 70516.216
N20: =Benchmarks!A20 -> Manager Finance and Administration | O20: =Benchmarks!B20 -> Ops | P20: =Benchmarks!D20 -> 565 | Q20: =Benchmarks!F20 -> 85162.369
N21: =Benchmarks!A21 -> Director, IT | O21: =Benchmarks!B21 -> IT | P21: =Benchmarks!D21 -> 685 | Q21: =Benchmarks!F21 -> 150078.79
